Workbook

Sheet Recensement DPS
A1: RECENSEMENT DES DPS
A2: Choisissez le nombre de DPS (0 à 5), puis écrivez-les dans la cellule voisine : Elaine P9 / Clotho P7
A3: Joueur | B3: 🔥 Feu Nb DPS | C3: 🔥 Feu DPS + potentiel | D3: ❄️ Glace Nb DPS | E3: ❄️ Glace DPS + potentiel | F3: 🌪️ Vent Nb DPS | G3: 🌪️ Vent DPS + potentiel | H3: 🌱 Terre Nb DPS | I3: 🌱 Terre DPS + potentiel | J3: ✨ Lumière Nb DPS | K3: ✨ Lumière DPS + potentiel | L3: 🌑 Ténèbres Nb DPS | M3: 🌑 Ténèbres DPS + potentiel | N3: ⚡ Foudre Nb DPS | O3: ⚡ Foudre DPS + potentiel
A4: Akaaarix | B4: 1 | C4: Escanor P8 | D4: 1 | E4: Merlin P10 | F4: 2 | G4: Elaine P6 / Clotho P4 | H4: 1 | I4: Diane P5 | J4: 2 | K4: Escanor P8 / King P7 | L4: 1 | M4: Meliodas P8 | N4: 1 | O4: Merlin P10
A5: Aion
A6: AiRoX7
A7: Altor
A8: Anto53
A9: BarracudaGN
A10: Behemoth
A11: Casté
A12: Eyael
A13: Fonzey
A14: Fruit11A
A15: Godgift
A16: iKeaght
... A24: TheFue

Sheet Analyse
A1: ANALYSE AUTOMATIQUE
A2: Sélectionnez un élément pour classer automatiquement tous les DPS selon leur potentiel.
A3: Élément | B3: Joueurs couverts | C3: DPS recensés | F3: Joueur | G3: Éléments couverts | H3: Total DPS | I3: Feu | J3: Glace | K3: Vent | L3: Terre | M3: Lumière | N3: Ténèbres | O3: Foudre
A4: 🔥 Feu | B4: =COUNTIF('Recensement DPS'!B4:B24,">0") -> 1 | C4: =SUM('Recensement DPS'!B4:B24) -> 1 | F4: Akaaarix | G4: {=COUNTIF({'Recensement DPS'!B4;'Recensement DPS'!D4;'Recensement DPS'!F4;'Recensement DPS'!H4;'Recensement DPS'!J4;'Recensement DPS'!L4;'Recensement DPS'!N4},">0")} -> 7 | H4: =SUM('Recensement DPS'!B4,'Recensement DPS'!D4,'Recensement DPS'!F4,'Recensement DPS'!H4,'Recensement DPS'!J4,'Recensement DPS'!L4,'Recensement DPS'!N4) -> 9 | I4: ='Recensement DPS'!C4 -> Escanor P8 | J4: ='Recensement DPS'!E4 -> Merlin P10 | K4: ='Recensement DPS'!G4 -> Elaine P6 / Clotho P4 | L4: ='Recensement DPS'!I4 -> Diane P5 | M4: ='Recensement DPS'!K4 -> Escanor P8 / King P7 | N4: ='Recensement DPS'!M4 -> Meliodas P8 | O4: ='Recensement DPS'!O4 -> Merlin P10
A5: ❄️ Glace | B5: =COUNTIF('Recensement DPS'!D4:D24,">0") -> 1 | C5: =SUM('Recensement DPS'!D4:D24) -> 1 | F5: Aion | G5: {=COUNTIF({'Recensement DPS'!B5;'Recensement DPS'!D5;'Recensement DPS'!F5;'Recensement DPS'!H5;'Recensement DPS'!J5;'Recensement DPS'!L5;'Recensement DPS'!N5},">0")} -> 0 | H5: =SUM('Recensement DPS'!B5,'Recensement DPS'!D5,'Recensement DPS'!F5,'Recensement DPS'!H5,'Recensement DPS'!J5,'Recensement DPS'!L5,'Recensement DPS'!N5) -> 0 | I5: ='Recensement DPS'!C5 | J5: ='Recensement DPS'!E5 | K5: ='Recensement DPS'!G5 | L5: ='Recensement DPS'!I5 | M5: ='Recensement DPS'!K5 | N5: ='Recensement DPS'!M5 | O5: ='Recensement DPS'!O5
A6: 🌪️ Vent | B6: =COUNTIF('Recensement DPS'!F4:F24,">0") -> 1 | C6: =SUM('Recensement DPS'!F4:F24) -> 2 | F6: AiRoX7 | G6: {=COUNTIF({'Recensement DPS'!B6;'Recensement DPS'!D6;'Recensement DPS'!F6;'Recensement DPS'!H6;'Recensement DPS'!J6;'Recensement DPS'!L6;'Recensement DPS'!N6},">0")} -> 0 | H6: =SUM('Recensement DPS'!B6,'Recensement DPS'!D6,'Recensement DPS'!F6,'Recensement DPS'!H6,'Recensement DPS'!J6,'Recensement DPS'!L6,'Recensement DPS'!N6) -> 0 | I6: ='Recensement DPS'!C6 | J6: ='Recensement DPS'!E6 | K6: ='Recensement DPS'!G6 | L6: ='Recensement DPS'!I6 | M6: ='Recensement DPS'!K6 | N6: ='Recensement DPS'!M6 | O6: ='Recensement DPS'!O6
A7: 🌱 Terre | B7: =COUNTIF('Recensement DPS'!H4:H24,">0") -> 1 | C7: =SUM('Recensement DPS'!H4:H24) -> 1 | F7: Altor | G7: {=COUNTIF({'Recensement DPS'!B7;'Recensement DPS'!D7;'Recensement DPS'!F7;'Recensement DPS'!H7;'Recensement DPS'!J7;'Recensement DPS'!L7;'Recensement DPS'!N7},">0")} -> 0 | H7: =SUM('Recensement DPS'!B7,'Recensement DPS'!D7,'Recensement DPS'!F7,'Recensement DPS'!H7,'Recensement DPS'!J7,'Recensement DPS'!L7,'Recensement DPS'!N7) -> 0 | I7: ='Recensement DPS'!C7 | J7: ='Recensement DPS'!E7 | K7: ='Recensement DPS'!G7 | L7: ='Recensement DPS'!I7 | M7: ='Recensement DPS'!K7 | N7: ='Recensement DPS'!M7 | O7: ='Recensement DPS'!O7
A8: ✨ Lumière | B8: =COUNTIF('Recensement DPS'!J4:J24,">0") -> 1 | C8: =SUM('Recensement DPS'!J4:J24) -> 2 | F8: Anto53 | G8: {=COUNTIF({'Recensement DPS'!B8;'Recensement DPS'!D8;'Recensement DPS'!F8;'Recensement DPS'!H8;'Recensement DPS'!J8;'Recensement DPS'!L8;'Recensement DPS'!N8},">0")} -> 0 | H8: =SUM('Recensement DPS'!B8,'Recensement DPS'!D8,'Recensement DPS'!F8,'Recensement DPS'!H8,'Recensement DPS'!J8,'Recensement DPS'!L8,'Recensement DPS'!N8) -> 0 | I8: ='Recensement DPS'!C8 | J8: ='Recensement DPS'!E8 | K8: ='Recensement DPS'!G8 | L8: ='Recensement DPS'!I8 | M8: ='Recensement DPS'!K8 | N8: ='Recensement DPS'!M8 | O8: ='Recensement DPS'!O8
A9: 🌑 Ténèbres | B9: =COUNTIF('Recensement DPS'!L4:L24,">0") -> 1 | C9: =SUM('Recensement DPS'!L4:L24) -> 1 | F9: BarracudaGN | G9: {=COUNTIF({'Recensement DPS'!B9;'Recensement DPS'!D9;'Recensement DPS'!F9;'Recensement DPS'!H9;'Recensement DPS'!J9;'Recensement DPS'!L9;'Recensement DPS'!N9},">0")} -> 0 | H9: =SUM('Recensement DPS'!B9,'Recensement DPS'!D9,'Recensement DPS'!F9,'Recensement DPS'!H9,'Recensement DPS'!J9,'Recensement DPS'!L9,'Recensement DPS'!N9) -> 0 | I9: ='Recensement DPS'!C9 | J9: ='Recensement DPS'!E9 | K9: ='Recensement DPS'!G9 | L9: ='Recensement DPS'!I9 | M9: ='Recensement DPS'!K9 | N9: ='Recensement DPS'!M9 | O9: ='Recensement DPS'!O9
A10: ⚡ Foudre | B10: =COUNTIF('Recensement DPS'!N4:N24,">0") -> 1 | C10: =SUM('Recensement DPS'!N4:N24) -> 1 | F10: Behemoth | G10: {=COUNTIF({'Recensement DPS'!B10;'Recensement DPS'!D10;'Recensement DPS'!F10;'Recensement DPS'!H10;'Recensement DPS'!J10;'Recensement DPS'!L10;'Recensement DPS'!N10},">0")} -> 0 | H10: =SUM('Recensement DPS'!B10,'Recensement DPS'!D10,'Recensement DPS'!F10,'Recensement DPS'!H10,'Recensement DPS'!J10,'Recensement DPS'!L10,'Recensement DPS'!N10) -> 0 | I10: ='Recensement DPS'!C10 | J10: ='Recensement DPS'!E10 | K10: ='Recensement DPS'!G10 | L10: ='Recensement DPS'!I10 | M10: ='Recensement DPS'!K10 | N10: ='Recensement DPS'!M10 | O10: ='Recensement DPS'!O10
F11: Casté | G11: {=COUNTIF({'Recensement DPS'!B11;'Recensement DPS'!D11;'Recensement DPS'!F11;'Recensement DPS'!H11;'Recensement DPS'!J11;'Recensement DPS'!L11;'Recensement DPS'!N11},">0")} -> 0 | H11: =SUM('Recensement DPS'!B11,'Recensement DPS'!D11,'Recensement DPS'!F11,'Recensement DPS'!H11,'Recensement DPS'!J11,'Recensement DPS'!L11,'Recensement DPS'!N11) -> 0 | I11: ='Recensement DPS'!C11 | J11: ='Recensement DPS'!E11 | K11: ='Recensement DPS'!G11 | L11: ='Recensement DPS'!I11 | M11: ='Recensement DPS'!K11 | N11: ='Recensement DPS'!M11 | O11: ='Recensement DPS'!O11
A12: CLASSEMENT PAR POTENTIEL | F12: Eyael | G12: {=COUNTIF({'Recensement DPS'!B12;'Recensement DPS'!D12;'Recensement DPS'!F12;'Recensement DPS'!H12;'Recensement DPS'!J12;'Recensement DPS'!L12;'Recensement DPS'!N12},">0")} -> 0 | H12: =SUM('Recensement DPS'!B12,'Recensement DPS'!D12,'Recensement DPS'!F12,'Recensement DPS'!H12,'Recensement DPS'!J12,'Recensement DPS'!L12,'Recensement DPS'!N12) -> 0 | I12: ='Recensement DPS'!C12 | J12: ='Recensement DPS'!E12 | K12: ='Recensement DPS'!G12 | L12: ='Recensement DPS'!I12 | M12: ='Recensement DPS'!K12 | N12: ='Recensement DPS'!M12 | O12: ='Recensement DPS'!O12
A13: Élément : | B13: Glace | F13: Fonzey | G13: {=COUNTIF({'Recensement DPS'!B13;'Recensement DPS'!D13;'Recensement DPS'!F13;'Recensement DPS'!H13;'Recensement DPS'!J13;'Recensement DPS'!L13;'Recensement DPS'!N13},">0")} -> 0 | H13: =SUM('Recensement DPS'!B13,'Recensement DPS'!D13,'Recensement DPS'!F13,'Recensement DPS'!H13,'Recensement DPS'!J13,'Recensement DPS'!L13,'Recensement DPS'!N13) -> 0 | I13: ='Recensement DPS'!C13 | J13: ='Recensement DPS'!E13 | K13: ='Recensement DPS'!G13 | L13: ='Recensement DPS'!I13 | M13: ='Recensement DPS'!K13 | N13: ='Recensement DPS'!M13 | O13: ='Recensement DPS'!O13
A14: Rang | B14: Joueur | C14: DPS | D14: Potentiel | F14: Fruit11A | G14: {=COUNTIF({'Recensement DPS'!B14;'Recensement DPS'!D14;'Recensement DPS'!F14;'Recensement DPS'!H14;'Recensement DPS'!J14;'Recensement DPS'!L14;'Recensement DPS'!N14},">0")} -> 0 | H14: =SUM('Recensement DPS'!B14,'Recensement DPS'!D14,'Recensement DPS'!F14,'Recensement DPS'!H14,'Recensement DPS'!J14,'Recensement DPS'!L14,'Recensement DPS'!N14) -> 0 | I14: ='Recensement DPS'!C14 | J14: ='Recensement DPS'!E14 | K14: ='Recensement DPS'!G14 | L14: ='Recensement DPS'!I14 | M14: ='Recensement DPS'!K14 | N14: ='Recensement DPS'!M14 | O14: ='Recensement DPS'!O14
A15: =IF(B15="","",ROW()-14) -> 1 | B15: =IFERROR(__xludf.DUMMYFUNCTION("IFERROR(SORT(FILTER(P15:R119,Q15:Q119<>""""),3,FALSE,2,TRUE),"""")"),"Akaaarix") -> Akaaarix | C15: =IFERROR(__xludf.DUMMYFUNCTION("""COMPUTED_VALUE"""),"Merlin P10") -> Merlin P10 | D15: =IFERROR(__xludf.DUMMYFUNCTION("""COMPUTED_VALUE"""),10.0) -> 10 | F15: Godgift | G15: {=COUNTIF({'Recensement DPS'!B15;'Recensement DPS'!D15;'Recensement DPS'!F15;'Recensement DPS'!H15;'Recensement DPS'!J15;'Recensement DPS'!L15;'Recensement DPS'!N15},">0")} -> 0 | H15: =SUM('Recensement DPS'!B15,'Recensement DPS'!D15,'Recensement DPS'!F15,'Recensement DPS'!H15,'Recensement DPS'!J15,'Recensement DPS'!L15,'Recensement DPS'!N15) -> 0 | I15: ='Recensement DPS'!C15 | J15: ='Recensement DPS'!E15 | K15: ='Recensement DPS'!G15 | L15: ='Recensement DPS'!I15 | M15: ='Recensement DPS'!K15 | N15: ='Recensement DPS'!M15 | O15: ='Recensement DPS'!O15 | P15: ='Recensement DPS'!A4 -> Akaaarix | Q15: =IFERROR(__xludf.DUMMYFUNCTION("IFERROR(INDEX(SPLIT(IF(REGEXMATCH(SWITCH($B$13,""Feu"",'Recensement DPS'!C4,""Glace"",'Recensement DPS'!E4,""Vent"",'Recensement DPS'!G4,""Terre"",'Recensement DPS'!I4,""Lumière"",'Recensement DPS'!K4,""Ténèbres"",'Recensement DPS'!M4,""Foudre"",'Recensem"&"ent DPS'!O4),""/""),SWITCH($B$13,""Feu"",'Recensement DPS'!C4,""Glace"",'Recensement DPS'!E4,""Vent"",'Recensement DPS'!G4,""Terre"",'Recensement DPS'!I4,""Lumière"",'Recensement DPS'!K4,""Ténèbres"",'Recensement DPS'!M4,""Foudre"",'Recensement DPS'!O4),R"&"EGEXREPLACE(SWITCH($B$13,""Feu"",'Recensement DPS'!C4,""Glace"",'Recensement DPS'!E4,""Vent"",'Recensement DPS'!G4,""Terre"",'Recensement DPS'!I4,""Lumière"",'Recensement DPS'!K4,""Ténèbres"",'Recensement DPS'!M4,""Foudre"",'Recensement DPS'!O4),""(?i)(P["&"0-9]+)\s+"",""$1 / "")),"" / "",FALSE,TRUE),1,1),"""")"),"Merlin P10") -> Merlin P10 | R15: =IFERROR(__xludf.DUMMYFUNCTION("IF(Q15="""","""",IFERROR(VALUE(REGEXEXTRACT(Q15,""(?i)P\s*([0-9]+)"")),""""))"),10.0) -> 10
A16: =IF(B16="","",ROW()-14) | F16: iKeaght | G16: {=COUNTIF({'Recensement DPS'!B16;'Recensement DPS'!D16;'Recensement DPS'!F16;'Recensement DPS'!H16;'Recensement DPS'!J16;'Recensement DPS'!L16;'Recensement DPS'!N16},">0")} -> 0 | H16: =SUM('Recensement DPS'!B16,'Recensement DPS'!D16,'Recensement DPS'!F16,'Recensement DPS'!H16,'Recensement DPS'!J16,'Recensement DPS'!L16,'Recensement DPS'!N16) -> 0 | I16: ='Recensement DPS'!C16 | J16: ='Recensement DPS'!E16 | K16: ='Recensement DPS'!G16 | L16: ='Recensement DPS'!I16 | M16: ='Recensement DPS'!K16 | N16: ='Recensement DPS'!M16 | O16: ='Recensement DPS'!O16 | P16: ='Recensement DPS'!A4 -> Akaaarix | Q16: =IFERROR(__xludf.DUMMYFUNCTION("IFERROR(INDEX(SPLIT(IF(REGEXMATCH(SWITCH($B$13,""Feu"",'Recensement DPS'!C4,""Glace"",'Recensement DPS'!E4,""Vent"",'Recensement DPS'!G4,""Terre"",'Recensement DPS'!I4,""Lumière"",'Recensement DPS'!K4,""Ténèbres"",'Recensement DPS'!M4,""Foudre"",'Recensem"&"ent DPS'!O4),""/""),SWITCH($B$13,""Feu"",'Recensement DPS'!C4,""Glace"",'Recensement DPS'!E4,""Vent"",'Recensement DPS'!G4,""Terre"",'Recensement DPS'!I4,""Lumière"",'Recensement DPS'!K4,""Ténèbres"",'Recensement DPS'!M4,""Foudre"",'Recensement DPS'!O4),R"&"EGEXREPLACE(SWITCH($B$13,""Feu"",'Recensement DPS'!C4,""Glace"",'Recensement DPS'!E4,""Vent"",'Recensement DPS'!G4,""Terre"",'Recensement DPS'!I4,""Lumière"",'Recensement DPS'!K4,""Ténèbres"",'Recensement DPS'!M4,""Foudre"",'Recensement DPS'!O4),""(?i)(P["&"0-9]+)\s+"",""$1 / "")),"" / "",FALSE,TRUE),1,2),"""")"),"") | R16: =IFERROR(__xludf.DUMMYFUNCTION("IF(Q16="""","""",IFERROR(VALUE(REGEXEXTRACT(Q16,""(?i)P\s*([0-9]+)"")),""""))"),"")
A17: =IF(B17="","",ROW()-14) | F17: Jinwoo | G17: {=COUNTIF({'Recensement DPS'!B17;'Recensement DPS'!D17;'Recensement DPS'!F17;'Recensement DPS'!H17;'Recensement DPS'!J17;'Recensement DPS'!L17;'Recensement DPS'!N17},">0")} -> 0 | H17: =SUM('Recensement DPS'!B17,'Recensement DPS'!D17,'Recensement DPS'!F17,'Recensement DPS'!H17,'Recensement DPS'!J17,'Recensement DPS'!L17,'Recensement DPS'!N17) -> 0 | I17: ='Recensement DPS'!C17 | J17: ='Recensement DPS'!E17 | K17: ='Recensement DPS'!G17 | L17: ='Recensement DPS'!I17 | M17: ='Recensement DPS'!K17 | N17: ='Recensement DPS'!M17 | O17: ='Recensement DPS'!O17 | P17: ='Recensement DPS'!A4 -> Akaaarix | Q17: =IFERROR(__xludf.DUMMYFUNCTION("IFERROR(INDEX(SPLIT(IF(REGEXMATCH(SWITCH($B$13,""Feu"",'Recensement DPS'!C4,""Glace"",'Recensement DPS'!E4,""Vent"",'Recensement DPS'!G4,""Terre"",'Recensement DPS'!I4,""Lumière"",'Recensement DPS'!K4,""Ténèbres"",'Recensement DPS'!M4,""Foudre"",'Recensem"&"ent DPS'!O4),""/""),SWITCH($B$13,""Feu"",'Recensement DPS'!C4,""Glace"",'Recensement DPS'!E4,""Vent"",'Recensement DPS'!G4,""Terre"",'Recensement DPS'!I4,""Lumière"",'Recensement DPS'!K4,""Ténèbres"",'Recensement DPS'!M4,""Foudre"",'Recensement DPS'!O4),R"&"EGEXREPLACE(SWITCH($B$13,""Feu"",'Recensement DPS'!C4,""Glace"",'Recensement DPS'!E4,""Vent"",'Recensement DPS'!G4,""Terre"",'Recensement DPS'!I4,""Lumière"",'Recensement DPS'!K4,""Ténèbres"",'Recensement DPS'!M4,""Foudre"",'Recensement DPS'!O4),""(?i)(P["&"0-9]+)\s+"",""$1 / "")),"" / "",FALSE,TRUE),1,3),"""")"),"") | R17: =IFERROR(__xludf.DUMMYFUNCTION("IF(Q17="""","""",IFERROR(VALUE(REGEXEXTRACT(Q17,""(?i)P\s*([0-9]+)"")),""""))"),"")
A18: =IF(B18="","",ROW()-14) | F18: Kirisaka | G18: {=COUNTIF({'Recensement DPS'!B18;'Recensement DPS'!D18;'Recensement DPS'!F18;'Recensement DPS'!H18;'Recensement DPS'!J18;'Recensement DPS'!L18;'Recensement DPS'!N18},">0")} -> 0 | H18: =SUM('Recensement DPS'!B18,'Recensement DPS'!D18,'Recensement DPS'!F18,'Recensement DPS'!H18,'Recensement DPS'!J18,'Recensement DPS'!L18,'Recensement DPS'!N18) -> 0 | I18: ='Recensement DPS'!C18 | J18: ='Recensement DPS'!E18 | K18: ='Recensement DPS'!G18 | L18: ='Recensement DPS'!I18 | M18: ='Recensement DPS'!K18 | N18: ='Recensement DPS'!M18 | O18: ='Recensement DPS'!O18 | P18: ='Recensement DPS'!A4 -> Akaaarix | Q18: =IFERROR(__xludf.DUMMYFUNCTION("IFERROR(INDEX(SPLIT(IF(REGEXMATCH(SWITCH($B$13,""Feu"",'Recensement DPS'!C4,""Glace"",'Recensement DPS'!E4,""Vent"",'Recensement DPS'!G4,""Terre"",'Recensement DPS'!I4,""Lumière"",'Recensement DPS'!K4,""Ténèbres"",'Recensement DPS'!M4,""Foudre"",'Recensem"&"ent DPS'!O4),""/""),SWITCH($B$13,""Feu"",'Recensement DPS'!C4,""Glace"",'Recensement DPS'!E4,""Vent"",'Recensement DPS'!G4,""Terre"",'Recensement DPS'!I4,""Lumière"",'Recensement DPS'!K4,""Ténèbres"",'Recensement DPS'!M4,""Foudre"",'Recensement DPS'!O4),R"&"EGEXREPLACE(SWITCH($B$13,""Feu"",'Recensement DPS'!C4,""Glace"",'Recensement DPS'!E4,""Vent"",'Recensement DPS'!G4,""Terre"",'Recensement DPS'!I4,""Lumière"",'Recensement DPS'!K4,""Ténèbres"",'Recensement DPS'!M4,""Foudre"",'Recensement DPS'!O4),""(?i)(P["&"0-9]+)\s+"",""$1 / "")),"" / "",FALSE,TRUE),1,4),"""")"),"") | R18: =IFERROR(__xludf.DUMMYFUNCTION("IF(Q18="""","""",IFERROR(VALUE(REGEXEXTRACT(Q18,""(?i)P\s*([0-9]+)"")),""""))"),"")
A19: =IF(B19="","",ROW()-14) | F19: MDK95 | G19: {=COUNTIF({'Recensement DPS'!B19;'Recensement DPS'!D19;'Recensement DPS'!F19;'Recensement DPS'!H19;'Recensement DPS'!J19;'Recensement DPS'!L19;'Recensement DPS'!N19},">0")} -> 0 | H19: =SUM('Recensement DPS'!B19,'Recensement DPS'!D19,'Recensement DPS'!F19,'Recensement DPS'!H19,'Recensement DPS'!J19,'Recensement DPS'!L19,'Recensement DPS'!N19) -> 0 | I19: ='Recensement DPS'!C19 | J19: ='Recensement DPS'!E19 | K19: ='Recensement DPS'!G19 | L19: ='Recensement DPS'!I19 | M19: ='Recensement DPS'!K19 | N19: ='Recensement DPS'!M19 | O19: ='Recensement DPS'!O19 | P19: ='Recensement DPS'!A4 -> Akaaarix | Q19: =IFERROR(__xludf.DUMMYFUNCTION("IFERROR(INDEX(SPLIT(IF(REGEXMATCH(SWITCH($B$13,""Feu"",'Recensement DPS'!C4,""Glace"",'Recensement DPS'!E4,""Vent"",'Recensement DPS'!G4,""Terre"",'Recensement DPS'!I4,""Lumière"",'Recensement DPS'!K4,""Ténèbres"",'Recensement DPS'!M4,""Foudre"",'Recensem"&"ent DPS'!O4),""/""),SWITCH($B$13,""Feu"",'Recensement DPS'!C4,""Glace"",'Recensement DPS'!E4,""Vent"",'Recensement DPS'!G4,""Terre"",'Recensement DPS'!I4,""Lumière"",'Recensement DPS'!K4,""Ténèbres"",'Recensement DPS'!M4,""Foudre"",'Recensement DPS'!O4),R"&"EGEXREPLACE(SWITCH($B$13,""Feu"",'Recensement DPS'!C4,""Glace"",'Recensement DPS'!E4,""Vent"",'Recensement DPS'!G4,""Terre"",'Recensement DPS'!I4,""Lumière"",'Recensement DPS'!K4,""Ténèbres"",'Recensement DPS'!M4,""Foudre"",'Recensement DPS'!O4),""(?i)(P["&"0-9]+)\s+"",""$1 / "")),"" / "",FALSE,TRUE),1,5),"""")"),"") | R19: =IFERROR(__xludf.DUMMYFUNCTION("IF(Q19="""","""",IFERROR(VALUE(REGEXEXTRACT(Q19,""(?i)P\s*([0-9]+)"")),""""))"),"")
A20: =IF(B20="","",ROW()-14) | F20: Mumu | G20: {=COUNTIF({'Recensement DPS'!B20;'Recensement DPS'!D20;'Recensement DPS'!F20;'Recensement DPS'!H20;'Recensement DPS'!J20;'Recensement DPS'!L20;'Recensement DPS'!N20},">0")} -> 0 | H20: =SUM('Recensement DPS'!B20,'Recensement DPS'!D20,'Recensement DPS'!F20,'Recensement DPS'!H20,'Recensement DPS'!J20,'Recensement DPS'!L20,'Recensement DPS'!N20) -> 0 | I20: ='Recensement DPS'!C20 | J20: ='Recensement DPS'!E20 | K20: ='Recensement DPS'!G20 | L20: ='Recensement DPS'!I20 | M20: ='Recensement DPS'!K20 | N20: ='Recensement DPS'!M20 | O20: ='Recensement DPS'!O20 | P20: ='Recensement DPS'!A5 -> Aion | Q20: =IFERROR(__xludf.DUMMYFUNCTION("IFERROR(INDEX(SPLIT(IF(REGEXMATCH(SWITCH($B$13,""Feu"",'Recensement DPS'!C5,""Glace"",'Recensement DPS'!E5,""Vent"",'Recensement DPS'!G5,""Terre"",'Recensement DPS'!I5,""Lumière"",'Recensement DPS'!K5,""Ténèbres"",'Recensement DPS'!M5,""Foudre"",'Recensem"&"ent DPS'!O5),""/""),SWITCH($B$13,""Feu"",'Recensement DPS'!C5,""Glace"",'Recensement DPS'!E5,""Vent"",'Recensement DPS'!G5,""Terre"",'Recensement DPS'!I5,""Lumière"",'Recensement DPS'!K5,""Ténèbres"",'Recensement DPS'!M5,""Foudre"",'Recensement DPS'!O5),R"&"EGEXREPLACE(SWITCH($B$13,""Feu"",'Recensement DPS'!C5,""Glace"",'Recensement DPS'!E5,""Vent"",'Recensement DPS'!G5,""Terre"",'Recensement DPS'!I5,""Lumière"",'Recensement DPS'!K5,""Ténèbres"",'Recensement DPS'!M5,""Foudre"",'Recensement DPS'!O5),""(?i)(P["&"0-9]+)\s+"",""$1 / "")),"" / "",FALSE,TRUE),1,1),"""")"),"") | R20: =IFERROR(__xludf.DUMMYFUNCTION("IF(Q20="""","""",IFERROR(VALUE(REGEXEXTRACT(Q20,""(?i)P\s*([0-9]+)"")),""""))"),"")
A21: =IF(B21="","",ROW()-14) | F21: Smiiters | G21: {=COUNTIF({'Recensement DPS'!B21;'Recensement DPS'!D21;'Recensement DPS'!F21;'Recensement DPS'!H21;'Recensement DPS'!J21;'Recensement DPS'!L21;'Recensement DPS'!N21},">0")} -> 0 | H21: =SUM('Recensement DPS'!B21,'Recensement DPS'!D21,'Recensement DPS'!F21,'Recensement DPS'!H21,'Recensement DPS'!J21,'Recensement DPS'!L21,'Recensement DPS'!N21) -> 0 | I21: ='Recensement DPS'!C21 | J21: ='Recensement DPS'!E21 | K21: ='Recensement DPS'!G21 | L21: ='Recensement DPS'!I21 | M21: ='Recensement DPS'!K21 | N21: ='Recensement DPS'!M21 | O21: ='Recensement DPS'!O21 | P21: ='Recensement DPS'!A5 -> Aion | Q21: =IFERROR(__xludf.DUMMYFUNCTION("IFERROR(INDEX(SPLIT(IF(REGEXMATCH(SWITCH($B$13,""Feu"",'Recensement DPS'!C5,""Glace"",'Recensement DPS'!E5,""Vent"",'Recensement DPS'!G5,""Terre"",'Recensement DPS'!I5,""Lumière"",'Recensement DPS'!K5,""Ténèbres"",'Recensement DPS'!M5,""Foudre"",'Recensem"&"ent DPS'!O5),""/""),SWITCH($B$13,""Feu"",'Recensement DPS'!C5,""Glace"",'Recensement DPS'!E5,""Vent"",'Recensement DPS'!G5,""Terre"",'Recensement DPS'!I5,""Lumière"",'Recensement DPS'!K5,""Ténèbres"",'Recensement DPS'!M5,""Foudre"",'Recensement DPS'!O5),R"&"EGEXREPLACE(SWITCH($B$13,""Feu"",'Recensement DPS'!C5,""Glace"",'Recensement DPS'!E5,""Vent"",'Recensement DPS'!G5,""Terre"",'Recensement DPS'!I5,""Lumière"",'Recensement DPS'!K5,""Ténèbres"",'Recensement DPS'!M5,""Foudre"",'Recensement DPS'!O5),""(?i)(P["&"0-9]+)\s+"",""$1 / "")),"" / "",FALSE,TRUE),1,2),"""")"),"") | R21: =IFERROR(__xludf.DUMMYFUNCTION("IF(Q21="""","""",IFERROR(VALUE(REGEXEXTRACT(Q21,""(?i)P\s*([0-9]+)"")),""""))"),"")
A22: =IF(B22="","",ROW()-14) | F22: Sucemonkbo974 | G22: {=COUNTIF({'Recensement DPS'!B22;'Recensement DPS'!D22;'Recensement DPS'!F22;'Recensement DPS'!H22;'Recensement DPS'!J22;'Recensement DPS'!L22;'Recensement DPS'!N22},">0")} -> 0 | H22: =SUM('Recensement DPS'!B22,'Recensement DPS'!D22,'Recensement DPS'!F22,'Recensement DPS'!H22,'Recensement DPS'!J22,'Recensement DPS'!L22,'Recensement DPS'!N22) -> 0 | I22: ='Recensement DPS'!C22 | J22: ='Recensement DPS'!E22 | K22: ='Recensement DPS'!G22 | L22: ='Recensement DPS'!I22 | M22: ='Recensement DPS'!K22 | N22: ='Recensement DPS'!M22 | O22: ='Recensement DPS'!O22 | P22: ='Recensement DPS'!A5 -> Aion | Q22: =IFERROR(__xludf.DUMMYFUNCTION("IFERROR(INDEX(SPLIT(IF(REGEXMATCH(SWITCH($B$13,""Feu"",'Recensement DPS'!C5,""Glace"",'Recensement DPS'!E5,""Vent"",'Recensement DPS'!G5,""Terre"",'Recensement DPS'!I5,""Lumière"",'Recensement DPS'!K5,""Ténèbres"",'Recensement DPS'!M5,""Foudre"",'Recensem"&"ent DPS'!O5),""/""),SWITCH($B$13,""Feu"",'Recensement DPS'!C5,""Glace"",'Recensement DPS'!E5,""Vent"",'Recensement DPS'!G5,""Terre"",'Recensement DPS'!I5,""Lumière"",'Recensement DPS'!K5,""Ténèbres"",'Recensement DPS'!M5,""Foudre"",'Recensement DPS'!O5),R"&"EGEXREPLACE(SWITCH($B$13,""Feu"",'Recensement DPS'!C5,""Glace"",'Recensement DPS'!E5,""Vent"",'Recensement DPS'!G5,""Terre"",'Recensement DPS'!I5,""Lumière"",'Recensement DPS'!K5,""Ténèbres"",'Recensement DPS'!M5,""Foudre"",'Recensement DPS'!O5),""(?i)(P["&"0-9]+)\s+"",""$1 / "")),"" / "",FALSE,TRUE),1,3),"""")"),"") | R22: =IFERROR(__xludf.DUMMYFUNCTION("IF(Q22="""","""",IFERROR(VALUE(REGEXEXTRACT(Q22,""(?i)P\s*([0-9]+)"")),""""))"),"")
A23: =IF(B23="","",ROW()-14) | F23: Syval | G23: {=COUNTIF({'Recensement DPS'!B23;'Recensement DPS'!D23;'Recensement DPS'!F23;'Recensement DPS'!H23;'Recensement DPS'!J23;'Recensement DPS'!L23;'Recensement DPS'!N23},">0")} -> 0 | H23: =SUM('Recensement DPS'!B23,'Recensement DPS'!D23,'Recensement DPS'!F23,'Recensement DPS'!H23,'Recensement DPS'!J23,'Recensement DPS'!L23,'Recensement DPS'!N23) -> 0 | I23: ='Recensement DPS'!C23 | J23: ='Recensement DPS'!E23 | K23: ='Recensement DPS'!G23 | L23: ='Recensement DPS'!I23 | M23: ='Recensement DPS'!K23 | N23: ='Recensement DPS'!M23 | O23: ='Recensement DPS'!O23 | P23: ='Recensement DPS'!A5 -> Aion | Q23: =IFERROR(__xludf.DUMMYFUNCTION("IFERROR(INDEX(SPLIT(IF(REGEXMATCH(SWITCH($B$13,""Feu"",'Recensement DPS'!C5,""Glace"",'Recensement DPS'!E5,""Vent"",'Recensement DPS'!G5,""Terre"",'Recensement DPS'!I5,""Lumière"",'Recensement DPS'!K5,""Ténèbres"",'Recensement DPS'!M5,""Foudre"",'Recensem"&"ent DPS'!O5),""/""),SWITCH($B$13,""Feu"",'Recensement DPS'!C5,""Glace"",'Recensement DPS'!E5,""Vent"",'Recensement DPS'!G5,""Terre"",'Recensement DPS'!I5,""Lumière"",'Recensement DPS'!K5,""Ténèbres"",'Recensement DPS'!M5,""Foudre"",'Recensement DPS'!O5),R"&"EGEXREPLACE(SWITCH($B$13,""Feu"",'Recensement DPS'!C5,""Glace"",'Recensement DPS'!E5,""Vent"",'Recensement DPS'!G5,""Terre"",'Recensement DPS'!I5,""Lumière"",'Recensement DPS'!K5,""Ténèbres"",'Recensement DPS'!M5,""Foudre"",'Recensement DPS'!O5),""(?i)(P["&"0-9]+)\s+"",""$1 / "")),"" / "",FALSE,TRUE),1,4),"""")"),"") | R23: =IFERROR(__xludf.DUMMYFUNCTION("IF(Q23="""","""",IFERROR(VALUE(REGEXEXTRACT(Q23,""(?i)P\s*([0-9]+)"")),""""))"),"")
A24: =IF(B24="","",ROW()-14) | F24: TheFue | G24: {=COUNTIF({'Recensement DPS'!B24;'Recensement DPS'!D24;'Recensement DPS'!F24;'Recensement DPS'!H24;'Recensement DPS'!J24;'Recensement DPS'!L24;'Recensement DPS'!N24},">0")} -> 0 | H24: =SUM('Recensement DPS'!B24,'Recensement DPS'!D24,'Recensement DPS'!F24,'Recensement DPS'!H24,'Recensement DPS'!J24,'Recensement DPS'!L24,'Recensement DPS'!N24) -> 0 | I24: ='Recensement DPS'!C24 | J24: ='Recensement DPS'!E24 | K24: ='Recensement DPS'!G24 | L24: ='Recensement DPS'!I24 | M24: ='Recensement DPS'!K24 | N24: ='Recensement DPS'!M24 | O24: ='Recensement DPS'!O24 | P24: ='Recensement DPS'!A5 -> Aion | Q24: =IFERROR(__xludf.DUMMYFUNCTION("IFERROR(INDEX(SPLIT(IF(REGEXMATCH(SWITCH($B$13,""Feu"",'Recensement DPS'!C5,""Glace"",'Recensement DPS'!E5,""Vent"",'Recensement DPS'!G5,""Terre"",'Recensement DPS'!I5,""Lumière"",'Recensement DPS'!K5,""Ténèbres"",'Recensement DPS'!M5,""Foudre"",'Recensem"&"ent DPS'!O5),""/""),SWITCH($B$13,""Feu"",'Recensement DPS'!C5,""Glace"",'Recensement DPS'!E5,""Vent"",'Recensement DPS'!G5,""Terre"",'Recensement DPS'!I5,""Lumière"",'Recensement DPS'!K5,""Ténèbres"",'Recensement DPS'!M5,""Foudre"",'Recensement DPS'!O5),R"&"EGEXREPLACE(SWITCH($B$13,""Feu"",'Recensement DPS'!C5,""Glace"",'Recensement DPS'!E5,""Vent"",'Recensement DPS'!G5,""Terre"",'Recensement DPS'!I5,""Lumière"",'Recensement DPS'!K5,""Ténèbres"",'Recensement DPS'!M5,""Foudre"",'Recensement DPS'!O5),""(?i)(P["&"0-9]+)\s+"",""$1 / "")),"" / "",FALSE,TRUE),1,5),"""")"),"") | R24: =IFERROR(__xludf.DUMMYFUNCTION("IF(Q24="""","""",IFERROR(VALUE(REGEXEXTRACT(Q24,""(?i)P\s*([0-9]+)"")),""""))"),"")
A25: =IF(B25="","",ROW()-14) | P25: ='Recensement DPS'!A6 -> AiRoX7 | Q25: =IFERROR(__xludf.DUMMYFUNCTION("IFERROR(INDEX(SPLIT(IF(REGEXMATCH(SWITCH($B$13,""Feu"",'Recensement DPS'!C6,""Glace"",'Recensement DPS'!E6,""Vent"",'Recensement DPS'!G6,""Terre"",'Recensement DPS'!I6,""Lumière"",'Recensement DPS'!K6,""Ténèbres"",'Recensement DPS'!M6,""Foudre"",'Recensem"&"ent DPS'!O6),""/""),SWITCH($B$13,""Feu"",'Recensement DPS'!C6,""Glace"",'Recensement DPS'!E6,""Vent"",'Recensement DPS'!G6,""Terre"",'Recensement DPS'!I6,""Lumière"",'Recensement DPS'!K6,""Ténèbres"",'Recensement DPS'!M6,""Foudre"",'Recensement DPS'!O6),R"&"EGEXREPLACE(SWITCH($B$13,""Feu"",'Recensement DPS'!C6,""Glace"",'Recensement DPS'!E6,""Vent"",'Recensement DPS'!G6,""Terre"",'Recensement DPS'!I6,""Lumière"",'Recensement DPS'!K6,""Ténèbres"",'Recensement DPS'!M6,""Foudre"",'Recensement DPS'!O6),""(?i)(P["&"0-9]+)\s+"",""$1 / "")),"" / "",FALSE,TRUE),1,1),"""")"),"") | R25: =IFERROR(__xludf.DUMMYFUNCTION("IF(Q25="""","""",IFERROR(VALUE(REGEXEXTRACT(Q25,""(?i)P\s*([0-9]+)"")),""""))"),"")
A26: =IF(B26="","",ROW()-14) | P26: ='Recensement DPS'!A6 -> AiRoX7 | Q26: =IFERROR(__xludf.DUMMYFUNCTION("IFERROR(INDEX(SPLIT(IF(REGEXMATCH(SWITCH($B$13,""Feu"",'Recensement DPS'!C6,""Glace"",'Recensement DPS'!E6,""Vent"",'Recensement DPS'!G6,""Terre"",'Recensement DPS'!I6,""Lumière"",'Recensement DPS'!K6,""Ténèbres"",'Recensement DPS'!M6,""Foudre"",'Recensem"&"ent DPS'!O6),""/""),SWITCH($B$13,""Feu"",'Recensement DPS'!C6,""Glace"",'Recensement DPS'!E6,""Vent"",'Recensement DPS'!G6,""Terre"",'Recensement DPS'!I6,""Lumière"",'Recensement DPS'!K6,""Ténèbres"",'Recensement DPS'!M6,""Foudre"",'Recensement DPS'!O6),R"&"EGEXREPLACE(SWITCH($B$13,""Feu"",'Recensement DPS'!C6,""Glace"",'Recensement DPS'!E6,""Vent"",'Recensement DPS'!G6,""Terre"",'Recensement DPS'!I6,""Lumière"",'Recensement DPS'!K6,""Ténèbres"",'Recensement DPS'!M6,""Foudre"",'Recensement DPS'!O6),""(?i)(P["&"0-9]+)\s+"",""$1 / "")),"" / "",FALSE,TRUE),1,2),"""")"),"") | R26: =IFERROR(__xludf.DUMMYFUNCTION("IF(Q26="""","""",IFERROR(VALUE(REGEXEXTRACT(Q26,""(?i)P\s*([0-9]+)"")),""""))"),"")
A27: =IF(B27="","",ROW()-14) | P27: ='Recensement DPS'!A6 -> AiRoX7 | Q27: =IFERROR(__xludf.DUMMYFUNCTION("IFERROR(INDEX(SPLIT(IF(REGEXMATCH(SWITCH($B$13,""Feu"",'Recensement DPS'!C6,""Glace"",'Recensement DPS'!E6,""Vent"",'Recensement DPS'!G6,""Terre"",'Recensement DPS'!I6,""Lumière"",'Recensement DPS'!K6,""Ténèbres"",'Recensement DPS'!M6,""Foudre"",'Recensem"&"ent DPS'!O6),""/""),SWITCH($B$13,""Feu"",'Recensement DPS'!C6,""Glace"",'Recensement DPS'!E6,""Vent"",'Recensement DPS'!G6,""Terre"",'Recensement DPS'!I6,""Lumière"",'Recensement DPS'!K6,""Ténèbres"",'Recensement DPS'!M6,""Foudre"",'Recensement DPS'!O6),R"&"EGEXREPLACE(SWITCH($B$13,""Feu"",'Recensement DPS'!C6,""Glace"",'Recensement DPS'!E6,""Vent"",'Recensement DPS'!G6,""Terre"",'Recensement DPS'!I6,""Lumière"",'Recensement DPS'!K6,""Ténèbres"",'Recensement DPS'!M6,""Foudre"",'Recensement DPS'!O6),""(?i)(P["&"0-9]+)\s+"",""$1 / "")),"" / "",FALSE,TRUE),1,3),"""")"),"") | R27: =IFERROR(__xludf.DUMMYFUNCTION("IF(Q27="""","""",IFERROR(VALUE(REGEXEXTRACT(Q27,""(?i)P\s*([0-9]+)"")),""""))"),"")
A28: =IF(B28="","",ROW()-14) | P28: ='Recensement DPS'!A6 -> AiRoX7 | Q28: =IFERROR(__xludf.DUMMYFUNCTION("IFERROR(INDEX(SPLIT(IF(REGEXMATCH(SWITCH($B$13,""Feu"",'Recensement DPS'!C6,""Glace"",'Recensement DPS'!E6,""Vent"",'Recensement DPS'!G6,""Terre"",'Recensement DPS'!I6,""Lumière"",'Recensement DPS'!K6,""Ténèbres"",'Recensement DPS'!M6,""Foudre"",'Recensem"&"ent DPS'!O6),""/""),SWITCH($B$13,""Feu"",'Recensement DPS'!C6,""Glace"",'Recensement DPS'!E6,""Vent"",'Recensement DPS'!G6,""Terre"",'Recensement DPS'!I6,""Lumière"",'Recensement DPS'!K6,""Ténèbres"",'Recensement DPS'!M6,""Foudre"",'Recensement DPS'!O6),R"&"EGEXREPLACE(SWITCH($B$13,""Feu"",'Recensement DPS'!C6,""Glace"",'Recensement DPS'!E6,""Vent"",'Recensement DPS'!G6,""Terre"",'Recensement DPS'!I6,""Lumière"",'Recensement DPS'!K6,""Ténèbres"",'Recensement DPS'!M6,""Foudre"",'Recensement DPS'!O6),""(?i)(P["&"0-9]+)\s+"",""$1 / "")),"" / "",FALSE,TRUE),1,4),"""")"),"") | R28: =IFERROR(__xludf.DUMMYFUNCTION("IF(Q28="""","""",IFERROR(VALUE(REGEXEXTRACT(Q28,""(?i)P\s*([0-9]+)"")),""""))"),"")
A29: =IF(B29="","",ROW()-14) | P29: ='Recensement DPS'!A6 -> AiRoX7 | Q29: =IFERROR(__xludf.DUMMYFUNCTION("IFERROR(INDEX(SPLIT(IF(REGEXMATCH(SWITCH($B$13,""Feu"",'Recensement DPS'!C6,""Glace"",'Recensement DPS'!E6,""Vent"",'Recensement DPS'!G6,""Terre"",'Recensement DPS'!I6,""Lumière"",'Recensement DPS'!K6,""Ténèbres"",'Recensement DPS'!M6,""Foudre"",'Recensem"&"ent DPS'!O6),""/""),SWITCH($B$13,""Feu"",'Recensement DPS'!C6,""Glace"",'Recensement DPS'!E6,""Vent"",'Recensement DPS'!G6,""Terre"",'Recensement DPS'!I6,""Lumière"",'Recensement DPS'!K6,""Ténèbres"",'Recensement DPS'!M6,""Foudre"",'Recensement DPS'!O6),R"&"EGEXREPLACE(SWITCH($B$13,""Feu"",'Recensement DPS'!C6,""Glace"",'Recensement DPS'!E6,""Vent"",'Recensement DPS'!G6,""Terre"",'Recensement DPS'!I6,""Lumière"",'Recensement DPS'!K6,""Ténèbres"",'Recensement DPS'!M6,""Foudre"",'Recensement DPS'!O6),""(?i)(P["&"0-9]+)\s+"",""$1 / "")),"" / "",FALSE,TRUE),1,5),"""")"),"") | R29: =IFERROR(__xludf.DUMMYFUNCTION("IF(Q29="""","""",IFERROR(VALUE(REGEXEXTRACT(Q29,""(?i)P\s*([0-9]+)"")),""""))"),"")
A30: =IF(B30="","",ROW()-14) | P30: ='Recensement DPS'!A7 -> Altor | Q30: =IFERROR(__xludf.DUMMYFUNCTION("IFERROR(INDEX(SPLIT(IF(REGEXMATCH(SWITCH($B$13,""Feu"",'Recensement DPS'!C7,""Glace"",'Recensement DPS'!E7,""Vent"",'Recensement DPS'!G7,""Terre"",'Recensement DPS'!I7,""Lumière"",'Recensement DPS'!K7,""Ténèbres"",'Recensement DPS'!M7,""Foudre"",'Recensem"&"ent DPS'!O7),""/""),SWITCH($B$13,""Feu"",'Recensement DPS'!C7,""Glace"",'Recensement DPS'!E7,""Vent"",'Recensement DPS'!G7,""Terre"",'Recensement DPS'!I7,""Lumière"",'Recensement DPS'!K7,""Ténèbres"",'Recensement DPS'!M7,""Foudre"",'Recensement DPS'!O7),R"&"EGEXREPLACE(SWITCH($B$13,""Feu"",'Recensement DPS'!C7,""Glace"",'Recensement DPS'!E7,""Vent"",'Recensement DPS'!G7,""Terre"",'Recensement DPS'!I7,""Lumière"",'Recensement DPS'!K7,""Ténèbres"",'Recensement DPS'!M7,""Foudre"",'Recensement DPS'!O7),""(?i)(P["&"0-9]+)\s+"",""$1 / "")),"" / "",FALSE,TRUE),1,1),"""")"),"") | R30: =IFERROR(__xludf.DUMMYFUNCTION("IF(Q30="""","""",IFERROR(VALUE(REGEXEXTRACT(Q30,""(?i)P\s*([0-9]+)"")),""""))"),"")
A31: =IF(B31="","",ROW()-14) | P31: ='Recensement DPS'!A7 -> Altor | Q31: =IFERROR(__xludf.DUMMYFUNCTION("IFERROR(INDEX(SPLIT(IF(REGEXMATCH(SWITCH($B$13,""Feu"",'Recensement DPS'!C7,""Glace"",'Recensement DPS'!E7,""Vent"",'Recensement DPS'!G7,""Terre"",'Recensement DPS'!I7,""Lumière"",'Recensement DPS'!K7,""Ténèbres"",'Recensement DPS'!M7,""Foudre"",'Recensem"&"ent DPS'!O7),""/""),SWITCH($B$13,""Feu"",'Recensement DPS'!C7,""Glace"",'Recensement DPS'!E7,""Vent"",'Recensement DPS'!G7,""Terre"",'Recensement DPS'!I7,""Lumière"",'Recensement DPS'!K7,""Ténèbres"",'Recensement DPS'!M7,""Foudre"",'Recensement DPS'!O7),R"&"EGEXREPLACE(SWITCH($B$13,""Feu"",'Recensement DPS'!C7,""Glace"",'Recensement DPS'!E7,""Vent"",'Recensement DPS'!G7,""Terre"",'Recensement DPS'!I7,""Lumière"",'Recensement DPS'!K7,""Ténèbres"",'Recensement DPS'!M7,""Foudre"",'Recensement DPS'!O7),""(?i)(P["&"0-9]+)\s+"",""$1 / "")),"" / "",FALSE,TRUE),1,2),"""")"),"") | R31: =IFERROR(__xludf.DUMMYFUNCTION("IF(Q31="""","""",IFERROR(VALUE(REGEXEXTRACT(Q31,""(?i)P\s*([0-9]+)"")),""""))"),"")
A32: =IF(B32="","",ROW()-14) | P32: ='Recensement DPS'!A7 -> Altor | Q32: =IFERROR(__xludf.DUMMYFUNCTION("IFERROR(INDEX(SPLIT(IF(REGEXMATCH(SWITCH($B$13,""Feu"",'Recensement DPS'!C7,""Glace"",'Recensement DPS'!E7,""Vent"",'Recensement DPS'!G7,""Terre"",'Recensement DPS'!I7,""Lumière"",'Recensement DPS'!K7,""Ténèbres"",'Recensement DPS'!M7,""Foudre"",'Recensem"&"ent DPS'!O7),""/""),SWITCH($B$13,""Feu"",'Recensement DPS'!C7,""Glace"",'Recensement DPS'!E7,""Vent"",'Recensement DPS'!G7,""Terre"",'Recensement DPS'!I7,""Lumière"",'Recensement DPS'!K7,""Ténèbres"",'Recensement DPS'!M7,""Foudre"",'Recensement DPS'!O7),R"&"EGEXREPLACE(SWITCH($B$13,""Feu"",'Recensement DPS'!C7,""Glace"",'Recensement DPS'!E7,""Vent"",'Recensement DPS'!G7,""Terre"",'Recensement DPS'!I7,""Lumière"",'Recensement DPS'!K7,""Ténèbres"",'Recensement DPS'!M7,""Foudre"",'Recensement DPS'!O7),""(?i)(P["&"0-9]+)\s+"",""$1 / "")),"" / "",FALSE,TRUE),1,3),"""")"),"") | R32: =IFERROR(__xludf.DUMMYFUNCTION("IF(Q32="""","""",IFERROR(VALUE(REGEXEXTRACT(Q32,""(?i)P\s*([0-9]+)"")),""""))"),"")
A33: =IF(B33="","",ROW()-14) | P33: ='Recensement DPS'!A7 -> Altor | Q33: =IFERROR(__xludf.DUMMYFUNCTION("IFERROR(INDEX(SPLIT(IF(REGEXMATCH(SWITCH($B$13,""Feu"",'Recensement DPS'!C7,""Glace"",'Recensement DPS'!E7,""Vent"",'Recensement DPS'!G7,""Terre"",'Recensement DPS'!I7,""Lumière"",'Recensement DPS'!K7,""Ténèbres"",'Recensement DPS'!M7,""Foudre"",'Recensem"&"ent DPS'!O7),""/""),SWITCH($B$13,""Feu"",'Recensement DPS'!C7,""Glace"",'Recensement DPS'!E7,""Vent"",'Recensement DPS'!G7,""Terre"",'Recensement DPS'!I7,""Lumière"",'Recensement DPS'!K7,""Ténèbres"",'Recensement DPS'!M7,""Foudre"",'Recensement DPS'!O7),R"&"EGEXREPLACE(SWITCH($B$13,""Feu"",'Recensement DPS'!C7,""Glace"",'Recensement DPS'!E7,""Vent"",'Recensement DPS'!G7,""Terre"",'Recensement DPS'!I7,""Lumière"",'Recensement DPS'!K7,""Ténèbres"",'Recensement DPS'!M7,""Foudre"",'Recensement DPS'!O7),""(?i)(P["&"0-9]+)\s+"",""$1 / "")),"" / "",FALSE,TRUE),1,4),"""")"),"") | R33: =IFERROR(__xludf.DUMMYFUNCTION("IF(Q33="""","""",IFERROR(VALUE(REGEXEXTRACT(Q33,""(?i)P\s*([0-9]+)"")),""""))"),"")
A34: =IF(B34="","",ROW()-14) | P34: ='Recensement DPS'!A7 -> Altor | Q34: =IFERROR(__xludf.DUMMYFUNCTION("IFERROR(INDEX(SPLIT(IF(REGEXMATCH(SWITCH($B$13,""Feu"",'Recensement DPS'!C7,""Glace"",'Recensement DPS'!E7,""Vent"",'Recensement DPS'!G7,""Terre"",'Recensement DPS'!I7,""Lumière"",'Recensement DPS'!K7,""Ténèbres"",'Recensement DPS'!M7,""Foudre"",'Recensem"&"ent DPS'!O7),""/""),SWITCH($B$13,""Feu"",'Recensement DPS'!C7,""Glace"",'Recensement DPS'!E7,""Vent"",'Recensement DPS'!G7,""Terre"",'Recensement DPS'!I7,""Lumière"",'Recensement DPS'!K7,""Ténèbres"",'Recensement DPS'!M7,""Foudre"",'Recensement DPS'!O7),R"&"EGEXREPLACE(SWITCH($B$13,""Feu"",'Recensement DPS'!C7,""Glace"",'Recensement DPS'!E7,""Vent"",'Recensement DPS'!G7,""Terre"",'Recensement DPS'!I7,""Lumière"",'Recensement DPS'!K7,""Ténèbres"",'Recensement DPS'!M7,""Foudre"",'Recensement DPS'!O7),""(?i)(P["&"0-9]+)\s+"",""$1 / "")),"" / "",FALSE,TRUE),1,5),"""")"),"") | R34: =IFERROR(__xludf.DUMMYFUNCTION("IF(Q34="""","""",IFERROR(VALUE(REGEXEXTRACT(Q34,""(?i)P\s*([0-9]+)"")),""""))"),"")
A35: =IF(B35="","",ROW()-14) | P35: ='Recensement DPS'!A8 -> Anto53 | Q35: =IFERROR(__xludf.DUMMYFUNCTION("IFERROR(INDEX(SPLIT(IF(REGEXMATCH(SWITCH($B$13,""Feu"",'Recensement DPS'!C8,""Glace"",'Recensement DPS'!E8,""Vent"",'Recensement DPS'!G8,""Terre"",'Recensement DPS'!I8,""Lumière"",'Recensement DPS'!K8,""Ténèbres"",'Recensement DPS'!M8,""Foudre"",'Recensem"&"ent DPS'!O8),""/""),SWITCH($B$13,""Feu"",'Recensement DPS'!C8,""Glace"",'Recensement DPS'!E8,""Vent"",'Recensement DPS'!G8,""Terre"",'Recensement DPS'!I8,""Lumière"",'Recensement DPS'!K8,""Ténèbres"",'Recensement DPS'!M8,""Foudre"",'Recensement DPS'!O8),R"&"EGEXREPLACE(SWITCH($B$13,""Feu"",'Recensement DPS'!C8,""Glace"",'Recensement DPS'!E8,""Vent"",'Recensement DPS'!G8,""Terre"",'Recensement DPS'!I8,""Lumière"",'Recensement DPS'!K8,""Ténèbres"",'Recensement DPS'!M8,""Foudre"",'Recensement DPS'!O8),""(?i)(P["&"0-9]+)\s+"",""$1 / "")),"" / "",FALSE,TRUE),1,1),"""")"),"") | R35: =IFERROR(__xludf.DUMMYFUNCTION("IF(Q35="""","""",IFERROR(VALUE(REGEXEXTRACT(Q35,""(?i)P\s*([0-9]+)"")),""""))"),"")
A36: =IF(B36="","",ROW()-14) | P36: ='Recensement DPS'!A8 -> Anto53 | Q36: =IFERROR(__xludf.DUMMYFUNCTION("IFERROR(INDEX(SPLIT(IF(REGEXMATCH(SWITCH($B$13,""Feu"",'Recensement DPS'!C8,""Glace"",'Recensement DPS'!E8,""Vent"",'Recensement DPS'!G8,""Terre"",'Recensement DPS'!I8,""Lumière"",'Recensement DPS'!K8,""Ténèbres"",'Recensement DPS'!M8,""Foudre"",'Recensem"&"ent DPS'!O8),""/""),SWITCH($B$13,""Feu"",'Recensement DPS'!C8,""Glace"",'Recensement DPS'!E8,""Vent"",'Recensement DPS'!G8,""Terre"",'Recensement DPS'!I8,""Lumière"",'Recensement DPS'!K8,""Ténèbres"",'Recensement DPS'!M8,""Foudre"",'Recensement DPS'!O8),R"&"EGEXREPLACE(SWITCH($B$13,""Feu"",'Recensement DPS'!C8,""Glace"",'Recensement DPS'!E8,""Vent"",'Recensement DPS'!G8,""Terre"",'Recensement DPS'!I8,""Lumière"",'Recensement DPS'!K8,""Ténèbres"",'Recensement DPS'!M8,""Foudre"",'Recensement DPS'!O8),""(?i)(P["&"0-9]+)\s+"",""$1 / "")),"" / "",FALSE,TRUE),1,2),"""")"),"") | R36: =IFERROR(__xludf.DUMMYFUNCTION("IF(Q36="""","""",IFERROR(VALUE(REGEXEXTRACT(Q36,""(?i)P\s*([0-9]+)"")),""""))"),"")
A37: =IF(B37="","",ROW()-14) | P37: ='Recensement DPS'!A8 -> Anto53 | Q37: =IFERROR(__xludf.DUMMYFUNCTION("IFERROR(INDEX(SPLIT(IF(REGEXMATCH(SWITCH($B$13,""Feu"",'Recensement DPS'!C8,""Glace"",'Recensement DPS'!E8,""Vent"",'Recensement DPS'!G8,""Terre"",'Recensement DPS'!I8,""Lumière"",'Recensement DPS'!K8,""Ténèbres"",'Recensement DPS'!M8,""Foudre"",'Recensem"&"ent DPS'!O8),""/""),SWITCH($B$13,""Feu"",'Recensement DPS'!C8,""Glace"",'Recensement DPS'!E8,""Vent"",'Recensement DPS'!G8,""Terre"",'Recensement DPS'!I8,""Lumière"",'Recensement DPS'!K8,""Ténèbres"",'Recensement DPS'!M8,""Foudre"",'Recensement DPS'!O8),R"&"EGEXREPLACE(SWITCH($B$13,""Feu"",'Recensement DPS'!C8,""Glace"",'Recensement DPS'!E8,""Vent"",'Recensement DPS'!G8,""Terre"",'Recensement DPS'!I8,""Lumière"",'Recensement DPS'!K8,""Ténèbres"",'Recensement DPS'!M8,""Foudre"",'Recensement DPS'!O8),""(?i)(P["&"0-9]+)\s+"",""$1 / "")),"" / "",FALSE,TRUE),1,3),"""")"),"") | R37: =IFERROR(__xludf.DUMMYFUNCTION("IF(Q37="""","""",IFERROR(VALUE(REGEXEXTRACT(Q37,""(?i)P\s*([0-9]+)"")),""""))"),"")
A38: =IF(B38="","",ROW()-14) | P38: ='Recensement DPS'!A8 -> Anto53 | Q38: =IFERROR(__xludf.DUMMYFUNCTION("IFERROR(INDEX(SPLIT(IF(REGEXMATCH(SWITCH($B$13,""Feu"",'Recensement DPS'!C8,""Glace"",'Recensement DPS'!E8,""Vent"",'Recensement DPS'!G8,""Terre"",'Recensement DPS'!I8,""Lumière"",'Recensement DPS'!K8,""Ténèbres"",'Recensement DPS'!M8,""Foudre"",'Recensem"&"ent DPS'!O8),""/""),SWITCH($B$13,""Feu"",'Recensement DPS'!C8,""Glace"",'Recensement DPS'!E8,""Vent"",'Recensement DPS'!G8,""Terre"",'Recensement DPS'!I8,""Lumière"",'Recensement DPS'!K8,""Ténèbres"",'Recensement DPS'!M8,""Foudre"",'Recensement DPS'!O8),R"&"EGEXREPLACE(SWITCH($B$13,""Feu"",'Recensement DPS'!C8,""Glace"",'Recensement DPS'!E8,""Vent"",'Recensement DPS'!G8,""Terre"",'Recensement DPS'!I8,""Lumière"",'Recensement DPS'!K8,""Ténèbres"",'Recensement DPS'!M8,""Foudre"",'Recensement DPS'!O8),""(?i)(P["&"0-9]+)\s+"",""$1 / "")),"" / "",FALSE,TRUE),1,4),"""")"),"") | R38: =IFERROR(__xludf.DUMMYFUNCTION("IF(Q38="""","""",IFERROR(VALUE(REGEXEXTRACT(Q38,""(?i)P\s*([0-9]+)"")),""""))"),"")
A39: =IF(B39="","",ROW()-14) | P39: ='Recensement DPS'!A8 -> Anto53 | Q39: =IFERROR(__xludf.DUMMYFUNCTION("IFERROR(INDEX(SPLIT(IF(REGEXMATCH(SWITCH($B$13,""Feu"",'Recensement DPS'!C8,""Glace"",'Recensement DPS'!E8,""Vent"",'Recensement DPS'!G8,""Terre"",'Recensement DPS'!I8,""Lumière"",'Recensement DPS'!K8,""Ténèbres"",'Recensement DPS'!M8,""Foudre"",'Recensem"&"ent DPS'!O8),""/""),SWITCH($B$13,""Feu"",'Recensement DPS'!C8,""Glace"",'Recensement DPS'!E8,""Vent"",'Recensement DPS'!G8,""Terre"",'Recensement DPS'!I8,""Lumière"",'Recensement DPS'!K8,""Ténèbres"",'Recensement DPS'!M8,""Foudre"",'Recensement DPS'!O8),R"&"EGEXREPLACE(SWITCH($B$13,""Feu"",'Recensement DPS'!C8,""Glace"",'Recensement DPS'!E8,""Vent"",'Recensement DPS'!G8,""Terre"",'Recensement DPS'!I8,""Lumière"",'Recensement DPS'!K8,""Ténèbres"",'Recensement DPS'!M8,""Foudre"",'Recensement DPS'!O8),""(?i)(P["&"0-9]+)\s+"",""$1 / "")),"" / "",FALSE,TRUE),1,5),"""")"),"") | R39: =IFERROR(__xludf.DUMMYFUNCTION("IF(Q39="""","""",IFERROR(VALUE(REGEXEXTRACT(Q39,""(?i)P\s*([0-9]+)"")),""""))"),"")
A40: =IF(B40="","",ROW()-14) | P40: ='Recensement DPS'!A9 -> BarracudaGN | Q40: =IFERROR(__xludf.DUMMYFUNCTION("IFERROR(INDEX(SPLIT(IF(REGEXMATCH(SWITCH($B$13,""Feu"",'Recensement DPS'!C9,""Glace"",'Recensement DPS'!E9,""Vent"",'Recensement DPS'!G9,""Terre"",'Recensement DPS'!I9,""Lumière"",'Recensement DPS'!K9,""Ténèbres"",'Recensement DPS'!M9,""Foudre"",'Recensem"&"ent DPS'!O9),""/""),SWITCH($B$13,""Feu"",'Recensement DPS'!C9,""Glace"",'Recensement DPS'!E9,""Vent"",'Recensement DPS'!G9,""Terre"",'Recensement DPS'!I9,""Lumière"",'Recensement DPS'!K9,""Ténèbres"",'Recensement DPS'!M9,""Foudre"",'Recensement DPS'!O9),R"&"EGEXREPLACE(SWITCH($B$13,""Feu"",'Recensement DPS'!C9,""Glace"",'Recensement DPS'!E9,""Vent"",'Recensement DPS'!G9,""Terre"",'Recensement DPS'!I9,""Lumière"",'Recensement DPS'!K9,""Ténèbres"",'Recensement DPS'!M9,""Foudre"",'Recensement DPS'!O9),""(?i)(P["&"0-9]+)\s+"",""$1 / "")),"" / "",FALSE,TRUE),1,1),"""")"),"") | R40: =IFERROR(__xludf.DUMMYFUNCTION("IF(Q40="""","""",IFERROR(VALUE(REGEXEXTRACT(Q40,""(?i)P\s*([0-9]+)"")),""""))"),"")
...
